<?xml version="1.0"?>
<robot xmlns:xacro="http://www.ros.org/wiki/xacro">
    <xacro:macro name="add_wheel" params="prefix radius thickness xyz parent">
        <joint name="${prefix}_joint" type="continuous" >
            <origin xyz="${xyz}" rpy="0 0 0"/>
            <parent link="${parent}"/>
            <child link="${prefix}_link"/>
            <axis xyz="0 1 0"/>
        </joint>

        <link name="${prefix}_link">
            <visual>
                <origin xyz="0 0 0" rpy="-1.5708 0 0"/>
                <geometry>
                    <cylinder radius="${radius}" length="${thickness}"/>
                </geometry>
                <material name="black"/>
            </visual>
            <collision>
                <origin xyz="0 0 0" rpy="-1.5708 0 0"/>
                <geometry>
                    <cylinder radius="${radius}" length="${thickness}"/>
                </geometry>
            </collision>
            <xacro:cylinder_inertial m="1" r="${radius}" l="${thickness}" xyz="0 0 0" rpy="0 0 0"/>
        </link>

        <gazebo reference="${prefix}_link">
            <material>Gazebo/Black</material>
        </gazebo>

    </xacro:macro>
</robot>
